Workbook

Sheet Start
C2: Palmetto Stay — Portfolio Release v1.0
C4: SYNTHETIC DATA: Palmetto Stay is fictional. All company-specific budgets, actuals, operating records, staffing information, and management updates are synthetic and contain no confidential company information.
C7: Workbook purpose | D7: Review recorded actuals and the approved budget, analyze first-half performance, and evaluate the 2026 RF1 Base, Upside, and Downside outlooks.
C8: Case version | D8: v1.0
C9: Current build status | D9: Portfolio Release v1.0 — independently validated within the project scope; actuals through June 2026; RF1 dated July 8, 2026.
C10: Analysis cutoff | D10: 46211
C11: Worksheet | D11: Role | E11: Portfolio release status
C12: Start | D12: Purpose, navigation, conventions, and use instructions | E12: Complete
C13: Data | D13: Frozen recorded actuals and dated case information | E13: Validated
C14: Assumptions | D14: Frozen approved 2026 budget drivers | E14: Validated
C15: Budget | D15: Formula-driven approved 2026 operating budget | E15: Complete
C16: Forecast | D16: Actualized forecast and scenarios | E16: Complete
C17: Variance | D17: Actual-versus-budget analysis | E17: Complete
C18: Review | D18: Two-page management-facing review | E18: Complete
C19: Checks | D19: Terminal source, model, aggregation, and package controls | E19: Complete
C21: Model-use instructions | D21: Review the frozen source tables, trace actuals through Variance, trace the outlook through Forecast and Assumptions, and inspect formulas before using results.
C22: Required control step | D22: Review the Checks tab before relying on this workbook. This instruction is static and is not linked to a check result.
C23: Later-phase status | D23: Portfolio Release v1.0 is complete: Budget, Variance, Forecast, Review, and all 179 terminal Checks are validated within the project scope.
C24: Expense convention | D24: Expenses are positive values and are subtracted when calculating property operating contribution.
C25: Variance convention | D25: Revenue and contribution use Actual minus Budget; expense tables also use Actual cost minus Budget cost, while contribution impacts reverse expense changes.
C28: Color and format legend | D28: Meaning
C29: Approved source input | D29: Blue font with pale-yellow fill
C30: Recorded source fact | D30: Dark text with pale-blue fill
C31: Cross-sheet formula | D31: Green font
C32: Same-sheet formula or result | D32: Black font
C34: Property | D34: One independently operated, leased limited-service hotel with 100 rooms
C35: Scope | D35: Room revenue and modeled property operating costs only

Sheet Data
C2: Frozen source data
C3: Static imports from case version v1.0. Actual KPIs and variances are intentionally not calculated on this sheet.
C5: Source: data/financial_actuals.csv | Case version: v1.0 | Static recorded facts
C7: case_version | D7: period | E7: account_code | F7: account_name | G7: amount_usd
C8: v1.0 | D8: 45658 | E8: 4000 | F8: Room Revenue | G8: 223203.5
C9: v1.0 | D9: 45658 | E9: 5000 | F9: Housekeeping Payroll | G9: 18834.45
C10: v1.0 | D10: 45658 | E10: 5100 | F10: Guest Services | G10: 28458
C11: v1.0 | D11: 45658 | E11: 5200 | F11: Distribution and Payment | G11: 8928.14
C12: v1.0 | D12: 45658 | E12: 6000 | F12: Fixed Staff Payroll | G12: 28750
C13: v1.0 | D13: 45658 | E13: 6100 | F13: Rent | G13: 76000
C14: v1.0 | D14: 45658 | E14: 6200 | F14: Property Overhead | G14: 26800
C15: v1.0 | D15: 45658 | E15: 6300 | F15: Marketing | G15: 9000
C16: v1.0 | D16: 45689 | E16: 4000 | F16: Room Revenue | G16: 221271
C17: v1.0 | D17: 45689 | E17: 5000 | F17: Housekeeping Payroll | G17: 18110.4
C18: v1.0 | D18: 45689 | E18: 5100 | F18: Guest Services | G18: 28028
C19: v1.0 | D19: 45689 | E19: 5200 | F19: Distribution and Payment | G19: 8850.84
... C151: v1.0 | D151: 46174 | E151: 6300 | F151: Marketing | G151: 6000
C155: Source: data/operating_actuals.csv | Case version: v1.0 | Static recorded facts
C157: case_version | D157: period | E157: segment | F157: occupied_room_nights | G157: room_revenue
C158: v1.0 | D158: 45658 | E158: Retail/Leisure | F158: 1154 | G158: 167907
C159: v1.0 | D159: 45658 | E159: Negotiated Corporate | F159: 427 | G159: 55296.5
C160: v1.0 | D160: 45689 | E160: Retail/Leisure | F160: 1109 | G160: 165241
C161: v1.0 | D161: 45689 | E161: Negotiated Corporate | F161: 431 | G161: 56030
C162: v1.0 | D162: 45717 | E162: Retail/Leisure | F162: 1367 | G162: 211201.5
C163: v1.0 | D163: 45717 | E163: Negotiated Corporate | F163: 586 | G163: 78231
C164: v1.0 | D164: 45748 | E164: Retail/Leisure | F164: 1387 | G164: 220533
C165: v1.0 | D165: 45748 | E165: Negotiated Corporate | F165: 623 | G165: 85974
C166: v1.0 | D166: 45778 | E166: Retail/Leisure | F166: 1518 | G166: 257301
C167: v1.0 | D167: 45778 | E167: Negotiated Corporate | F167: 714 | G167: 101745
C168: v1.0 | D168: 45809 | E168: Retail/Leisure | F168: 1505 | G168: 264127.5
C169: v1.0 | D169: 45809 | E169: Negotiated Corporate | F169: 775 | G169: 111987.5
... C193: v1.0 | D193: 46174 | E193: Negotiated Corporate | F193: 951 | G193: 141223.5
C197: Source: data/labor_actuals.csv | Case version: v1.0 | Static recorded facts
C199: case_version | D199: period | E199: housekeeping_hours | F199: housekeeping_payroll | G199: fixed_staff_fte | H199: fixed_staff_payroll
C200: v1.0 | D200: 45658 | E200: 901.17 | F200: 18834.45 | G200: 5 | H200: 28750
C201: v1.0 | D201: 45689 | E201: 862.4 | F201: 18110.4 | G201: 5 | H201: 28800
C202: v1.0 | D202: 45717 | E202: 1074.15 | F202: 22610.86 | G202: 4.9 | H202: 28322
C203: v1.0 | D203: 45748 | E203: 1105.5 | F203: 23436.6 | G203: 5 | H203: 29000
C204: v1.0 | D204: 45778 | E204: 1182.96 | F204: 25137.9 | G204: 5 | H204: 29100
C205: v1.0 | D205: 45809 | E205: 1208.4 | F205: 25738.92 | G205: 5 | H205: 29200
...

Sheet Assumptions
C2: Approved 2026 budget assumptions
C3: The frozen approved plan is the single authoritative source for the Budget sheet.
C5: Source: data/approved_budget_assumptions.csv | Case version: v1.0 | Approved before 2026 actual results
C7: case_version | D7: period | E7: rooms_available | F7: total_occupied_room_nights | G7: corporate_share | H7: retail_adr | I7: corporate_adr | J7: housekeeping_hours_per_occupied_room | K7: housekeeping_loaded_wage_per_hour | L7: guest_service_cost_per_occupied_room | M7: distribution_fee_rate | N7: fixed_staff_fte | O7: fixed_staff_loaded_cost_per_fte | P7: rent | Q7: property_overhead | R7: marketing
C8: v1.0 | D8: 46023 | E8: 100 | F8: 1705 | G8: 0.3 | H8: 150 | I8: 132 | J8: 0.56 | K8: 22 | L8: 18.5 | M8: 0.04 | N8: 5 | O8: 6000 | P8: 78000 | Q8: 28000 | R8: 10000
C9: v1.0 | D9: 46054 | E9: 100 | F9: 1624 | G9: 0.31 | H9: 152 | I9: 133 | J9: 0.55 | K9: 22 | L9: 18.7 | M9: 0.04 | N9: 5 | O9: 6000 | P9: 78000 | Q9: 28100 | R9: 9000
C10: v1.0 | D10: 46082 | E10: 100 | F10: 2015 | G10: 0.32 | H10: 158 | I10: 137 | J10: 0.54 | K10: 22 | L10: 19 | M10: 0.04 | N10: 5 | O10: 6000 | P10: 78000 | Q10: 28500 | R10: 11000
C11: v1.0 | D11: 46113 | E11: 100 | F11: 2100 | G11: 0.34 | H11: 164 | I11: 140 | J11: 0.53 | K11: 22 | L11: 19.2 | M11: 0.04 | N11: 5 | O11: 6000 | P11: 78000 | Q11: 28600 | R11: 13000
C12: v1.0 | D12: 46143 | E12: 100 | F12: 2294 | G12: 0.35 | H12: 172 | I12: 145 | J12: 0.52 | K12: 22 | L12: 19.5 | M12: 0.04 | N12: 5 | O12: 6000 | P12: 78000 | Q12: 28900 | R12: 14000
C13: v1.0 | D13: 46174 | E13: 100 | F13: 2340 | G13: 0.36 | H13: 180 | I13: 148 | J13: 0.51 | K13: 22 | L13: 19.8 | M13: 0.04 | N13: 5 | O13: 6000 | P13: 78000 | Q13: 29200 | R13: 24000
C14: v1.0 | D14: 46204 | E14: 100 | F14: 2604 | G14: 0.38 | H14: 188 | I14: 153 | J14: 0.5 | K14: 22.75 | L14: 20 | M14: 0.04 | N14: 5 | O14: 6120 | P14: 78000 | Q14: 29800 | R14: 18000
C15: v1.0 | D15: 46235 | E15: 100 | F15: 2542 | G15: 0.39 | H15: 185 | I15: 151 | J15: 0.5 | K15: 22.75 | L15: 20 | M15: 0.04 | N15: 5 | O15: 6120 | P15: 78000 | Q15: 30000 | R15: 15000
C16: v1.0 | D16: 46266 | E16: 100 | F16: 2190 | G16: 0.4 | H16: 175 | I16: 146 | J16: 0.52 | K16: 22.75 | L16: 19.8 | M16: 0.04 | N16: 5 | O16: 6120 | P16: 78000 | Q16: 29400 | R16: 12000
C17: v1.0 | D17: 46296 | E17: 100 | F17: 2201 | G17: 0.38 | H17: 170 | I17: 144 | J17: 0.53 | K17: 22.75 | L17: 19.5 | M17: 0.04 | N17: 5 | O17: 6120 | P17: 78000 | Q17: 29100 | R17: 13000
C18: v1.0 | D18: 46327 | E18: 100 | F18: 1830 | G18: 0.34 | H18: 158 | I18: 138 | J18: 0.55 | K18: 22.75 | L18: 19 | M18: 0.04 | N18: 5 | O18: 6120 | P18: 78000 | Q18: 28700 | R18: 12000
C19: v1.0 | D19: 46357 | E19: 100 | F19: 1829 | G19: 0.32 | H19: 162 | I19: 140 | J19: 0.56 | K19: 22.75 | L19: 19.2 | M19: 0.04 | N19: 5 | O19: 6120 | P19: 78000 | Q19: 29000 | R19: 16000
C22: Input treatment | D22: Static approved source values; do not overwrite for forecast or scenarios.
C23: Date convention | D23: Monthly period keys use the first day of each month.
C24: Budget link | D24: Budget formulas match each monthly header to this table.
C25: Formatting | D25: Blue font and pale-yellow fill identify approved source inputs.
C28: 2026 RF1 assumptions
C29: A later analytical layer for July–December 2026. The approved budget assumptions above remain frozen and are not overwritten.
C31: Forecast controls
C32: Forecast version | D32: 2026 RF1 | F32: Case version | G32: v1.0 | I32: Information cutoff | J32: 46211 | L32: Actual through | M32: 46174 | O32: First forecast | P32: 46204 | Q32: Last forecast | R32: 46357
C34: Base | D34: Official working reforecast: partial retail recovery, continued corporate support, structural wage rate, staged productivity normalization, and deferred September marketing.
C35: Upside | D35: Bounded sensitivity: stronger demand and pricing with faster housekeeping productivity normalization.
C36: Downside | D36: Bounded sensitivity: persistent demand weakness, less corporate offset, rate pressure, and slower productivity normalization.
C37: Scenario ranges support decisions; they are not probability weighted and are not confidence intervals. RF1 accuracy cannot be evaluated until later actuals exist.
C39: Base case monthly assumptions
C40: Driver | D40: Basis type | E40: Source / update | F40: Jul-26 | G40: Aug-26 | H40: Sep-26 | I40: Oct-26 | J40: Nov-26 | K40: Dec-26
C41: Rooms available | D41: Approved budget | E41: Approved assumption pack | F41: 100 | G41: 100 | H41: 100 | I41: 100 | J41: 100 | K41: 100
C42: Occupied room nights | D42: Analyst judgment | E42: UPD-2026-001, 002, 007 | F42: 2552 | G42: 2491 | H42: 2146 | I42: 2168 | J42: 1812 | K42: 1811
C43: Corporate share | D43: Actual run rate | E43: UPD-2026-002 | F43: 0.41 | G43: 0.42 | H43: 0.43 | I43: 0.405 | J43: 0.36 | K43: 0.335
C44: Retail ADR | D44: Approved budget | E44: Approved assumption pack | F44: 188 | G44: 185 | H44: 175 | I44: 170 | J44: 158 | K44: 162
C45: Corporate ADR | D45: Actual run rate | E45: Recorded actuals and budget | F45: 153.5 | G45: 151.5 | H45: 146.5 | I45: 144.5 | J45: 138.5 | K45: 140.5
C46: Housekeeping hours per occupied room | D46: Analyst judgment | E46: UPD-2026-004 | F46: 0.55 | G46: 0.54 | H46: 0.53 | I46: 0.53 | J46: 0.55 | K46: 0.56
C47: Housekeeping loaded wage per hour | D47: Case update | E47: UPD-2026-003 | F47: 23.25 | G47: 23.25 | H47: 23.25 | I47: 23.25 | J47: 23.25 | K47: 23.25
C48: Guest-service cost per occupied room | D48: Approved budget | E48: Approved assumption pack | F48: 20 | G48: 20 | H48: 19.8 | I48: 19.5 | J48: 19 | K48: 19.2
C49: Distribution fee rate | D49: Approved budget | E49: Locked 4% policy | F49: 0.04 | G49: 0.04 | H49: 0.04 | I49: 0.04 | J49: 0.04 | K49: 0.04
C50: Fixed-staff FTE | D50: Approved budget | E50: Approved assumption pack | F50: 5 | G50: 5 | H50: 5 | I50: 5 | J50: 5 | K50: 5
...

Sheet Budget
C2: Approved 2026 operating budget
C3: Formula-driven build from the frozen approved assumption pack. Expenses are shown as positive values.
C5: Metric | D5: 46023 | E5: 46054 | F5: 46082 | G5: 46113 | H5: 46143 | I5: 46174 | J5: 46204 | K5: 46235 | L5: 46266 | M5: 46296 | N5: 46327 | O5: 46357 | P5: FY2026
C6: FY column uses sums for additive lines and weighted or average calculations for rates and monthly levels.
C7: Operating drivers
C8: Rooms available | D8: =INDEX(Assumptions!$E$8:$E$19,MATCH(D$5,Assumptions!$D$8:$D$19,0)) -> 100 | E8: =INDEX(Assumptions!$E$8:$E$19,MATCH(E$5,Assumptions!$D$8:$D$19,0)) -> 100 | F8: =INDEX(Assumptions!$E$8:$E$19,MATCH(F$5,Assumptions!$D$8:$D$19,0)) -> 100 | G8: =INDEX(Assumptions!$E$8:$E$19,MATCH(G$5,Assumptions!$D$8:$D$19,0)) -> 100 | H8: =INDEX(Assumptions!$E$8:$E$19,MATCH(H$5,Assumptions!$D$8:$D$19,0)) -> 100 | I8: =INDEX(Assumptions!$E$8:$E$19,MATCH(I$5,Assumptions!$D$8:$D$19,0)) -> 100 | J8: =INDEX(Assumptions!$E$8:$E$19,MATCH(J$5,Assumptions!$D$8:$D$19,0)) -> 100 | K8: =INDEX(Assumptions!$E$8:$E$19,MATCH(K$5,Assumptions!$D$8:$D$19,0)) -> 100 | ... O8: =INDEX(Assumptions!$E$8:$E$19,MATCH(O$5,Assumptions!$D$8:$D$19,0)) -> 100 | P8: =AVERAGE(D8:O8) -> 100
C9: Calendar days | D9: =DATE(YEAR(D$5),MONTH(D$5)+1,1)-D$5 -> 31 | E9: =DATE(YEAR(E$5),MONTH(E$5)+1,1)-E$5 -> 28 | F9: =DATE(YEAR(F$5),MONTH(F$5)+1,1)-F$5 -> 31 | G9: =DATE(YEAR(G$5),MONTH(G$5)+1,1)-G$5 -> 30 | H9: =DATE(YEAR(H$5),MONTH(H$5)+1,1)-H$5 -> 31 | I9: =DATE(YEAR(I$5),MONTH(I$5)+1,1)-I$5 -> 30 | J9: =DATE(YEAR(J$5),MONTH(J$5)+1,1)-J$5 -> 31 | K9: =DATE(YEAR(K$5),MONTH(K$5)+1,1)-K$5 -> 31 | ... O9: =DATE(YEAR(O$5),MONTH(O$5)+1,1)-O$5 -> 31 | P9: =SUM(D9:O9) -> 365
C10: Available room nights | D10: =D8*D9 -> 3100 | E10: =E8*E9 -> 2800 | F10: =F8*F9 -> 3100 | G10: =G8*G9 -> 3000 | H10: =H8*H9 -> 3100 | I10: =I8*I9 -> 3000 | J10: =J8*J9 -> 3100 | K10: =K8*K9 -> 3100 | ... O10: =O8*O9 -> 3100 | P10: =SUM(D10:O10) -> 36500
C11: Total occupied room nights | D11: =INDEX(Assumptions!$F$8:$F$19,MATCH(D$5,Assumptions!$D$8:$D$19,0)) -> 1705 | E11: =INDEX(Assumptions!$F$8:$F$19,MATCH(E$5,Assumptions!$D$8:$D$19,0)) -> 1624 | F11: =INDEX(Assumptions!$F$8:$F$19,MATCH(F$5,Assumptions!$D$8:$D$19,0)) -> 2015 | G11: =INDEX(Assumptions!$F$8:$F$19,MATCH(G$5,Assumptions!$D$8:$D$19,0)) -> 2100 | H11: =INDEX(Assumptions!$F$8:$F$19,MATCH(H$5,Assumptions!$D$8:$D$19,0)) -> 2294 | I11: =INDEX(Assumptions!$F$8:$F$19,MATCH(I$5,Assumptions!$D$8:$D$19,0)) -> 2340 | J11: =INDEX(Assumptions!$F$8:$F$19,MATCH(J$5,Assumptions!$D$8:$D$19,0)) -> 2604 | K11: =INDEX(Assumptions!$F$8:$F$19,MATCH(K$5,Assumptions!$D$8:$D$19,0)) -> 2542 | ... O11: =INDEX(Assumptions!$F$8:$F$19,MATCH(O$5,Assumptions!$D$8:$D$19,0)) -> 1829 | P11: =SUM(D11:O11) -> 25274
C12: Occupancy | D12: =D11/D10 -> 0.55 | E12: =E11/E10 -> 0.58 | F12: =F11/F10 -> 0.65 | G12: =G11/G10 -> 0.7 | H12: =H11/H10 -> 0.74 | I12: =I11/I10 -> 0.78 | J12: =J11/J10 -> 0.84 | K12: =K11/K10 -> 0.82 | ... P12: =P11/P10 -> 0.69243836
C13: Corporate share | D13: =INDEX(Assumptions!$G$8:$G$19,MATCH(D$5,Assumptions!$D$8:$D$19,0)) -> 0.3 | E13: =INDEX(Assumptions!$G$8:$G$19,MATCH(E$5,Assumptions!$D$8:$D$19,0)) -> 0.31 | F13: =INDEX(Assumptions!$G$8:$G$19,MATCH(F$5,Assumptions!$D$8:$D$19,0)) -> 0.32 | G13: =INDEX(Assumptions!$G$8:$G$19,MATCH(G$5,Assumptions!$D$8:$D$19,0)) -> 0.34 | H13: =INDEX(Assumptions!$G$8:$G$19,MATCH(H$5,Assumptions!$D$8:$D$19,0)) -> 0.35 | I13: =INDEX(Assumptions!$G$8:$G$19,MATCH(I$5,Assumptions!$D$8:$D$19,0)) -> 0.36 | J13: =INDEX(Assumptions!$G$8:$G$19,MATCH(J$5,Assumptions!$D$8:$D$19,0)) -> 0.38 | K13: =INDEX(Assumptions!$G$8:$G$19,MATCH(K$5,Assumptions!$D$8:$D$19,0)) -> 0.39 | ... O13: =INDEX(Assumptions!$G$8:$G$19,MATCH(O$5,Assumptions!$D$8:$D$19,0)) -> 0.32 | P13: =P15/P11 -> 0.35292395
C14: Retail room nights | D14: =D11-D15 -> 1193.5 | E14: =E11-E15 -> 1120.56 | F14: =F11-F15 -> 1370.2 | G14: =G11-G15 -> 1386 | H14: =H11-H15 -> 1491.1 | I14: =I11-I15 -> 1497.6 | J14: =J11-J15 -> 1614.48 | K14: =K11-K15 -> 1550.62 | ... O14: =O11-O15 -> 1243.72 | P14: =SUM(D14:O14) -> 16354.2
C15: Corporate room nights | D15: =D11*D13 -> 511.5 | E15: =E11*E13 -> 503.44 | F15: =F11*F13 -> 644.8 | G15: =G11*G13 -> 714 | H15: =H11*H13 -> 802.9 | I15: =I11*I13 -> 842.4 | J15: =J11*J13 -> 989.52 | K15: =K11*K13 -> 991.38 | ... O15: =O11*O13 -> 585.28 | P15: =SUM(D15:O15) -> 8919.8
C16: Retail ADR | D16: =INDEX(Assumptions!$H$8:$H$19,MATCH(D$5,Assumptions!$D$8:$D$19,0)) -> 150 | E16: =INDEX(Assumptions!$H$8:$H$19,MATCH(E$5,Assumptions!$D$8:$D$19,0)) -> 152 | F16: =INDEX(Assumptions!$H$8:$H$19,MATCH(F$5,Assumptions!$D$8:$D$19,0)) -> 158 | G16: =INDEX(Assumptions!$H$8:$H$19,MATCH(G$5,Assumptions!$D$8:$D$19,0)) -> 164 | H16: =INDEX(Assumptions!$H$8:$H$19,MATCH(H$5,Assumptions!$D$8:$D$19,0)) -> 172 | I16: =INDEX(Assumptions!$H$8:$H$19,MATCH(I$5,Assumptions!$D$8:$D$19,0)) -> 180 | J16: =INDEX(Assumptions!$H$8:$H$19,MATCH(J$5,Assumptions!$D$8:$D$19,0)) -> 188 | K16: =INDEX(Assumptions!$H$8:$H$19,MATCH(K$5,Assumptions!$D$8:$D$19,0)) -> 185 | ... O16: =INDEX(Assumptions!$H$8:$H$19,MATCH(O$5,Assumptions!$D$8:$D$19,0)) -> 162 | P16: =P21/P14 -> 168.99758
C17: Corporate ADR | D17: =INDEX(Assumptions!$I$8:$I$19,MATCH(D$5,Assumptions!$D$8:$D$19,0)) -> 132 | E17: =INDEX(Assumptions!$I$8:$I$19,MATCH(E$5,Assumptions!$D$8:$D$19,0)) -> 133 | F17: =INDEX(Assumptions!$I$8:$I$19,MATCH(F$5,Assumptions!$D$8:$D$19,0)) -> 137 | G17: =INDEX(Assumptions!$I$8:$I$19,MATCH(G$5,Assumptions!$D$8:$D$19,0)) -> 140 | H17: =INDEX(Assumptions!$I$8:$I$19,MATCH(H$5,Assumptions!$D$8:$D$19,0)) -> 145 | I17: =INDEX(Assumptions!$I$8:$I$19,MATCH(I$5,Assumptions!$D$8:$D$19,0)) -> 148 | J17: =INDEX(Assumptions!$I$8:$I$19,MATCH(J$5,Assumptions!$D$8:$D$19,0)) -> 153 | K17: =INDEX(Assumptions!$I$8:$I$19,MATCH(K$5,Assumptions!$D$8:$D$19,0)) -> 151 | ... O17: =INDEX(Assumptions!$I$8:$I$19,MATCH(O$5,Assumptions!$D$8:$D$19,0)) -> 140 | P17: =P22/P15 -> 143.62444
C20: Revenue
C21: Retail room revenue | D21: =D14*D16 -> 179025 | E21: =E14*E16 -> 170325.12 | F21: =F14*F16 -> 216491.6 | G21: =G14*G16 -> 227304 | H21: =H14*H16 -> 256469.2 | I21: =I14*I16 -> 269568 | J21: =J14*J16 -> 303522.24 | K21: =K14*K16 -> 286864.7 | ... O21: =O14*O16 -> 201482.64 | P21: =SUM(D21:O21) -> 2763820.3
C22: Corporate room revenue | D22: =D15*D17 -> 67518 | E22: =E15*E17 -> 66957.52 | F22: =F15*F17 -> 88337.6 | G22: =G15*G17 -> 99960 | H22: =H15*H17 -> 116420.5 | I22: =I15*I17 -> 124675.2 | J22: =J15*J17 -> 151396.56 | K22: =K15*K17 -> 149698.38 | ... O22: =O15*O17 -> 81939.2 | P22: =SUM(D22:O22) -> 1281101.3
C23: Total room revenue | D23: =SUM(D21:D22) -> 246543 | E23: =SUM(E21:E22) -> 237282.64 | F23: =SUM(F21:F22) -> 304829.2 | G23: =SUM(G21:G22) -> 327264 | H23: =SUM(H21:H22) -> 372889.7 | I23: =SUM(I21:I22) -> 394243.2 | J23: =SUM(J21:J22) -> 454918.8 | K23: =SUM(K21:K22) -> 436563.08 | ... O23: =SUM(O21:O22) -> 283421.84 | P23: =SUM(D23:O23) -> 4044921.6
C24: Blended ADR | D24: =D23/D11 -> 144.6 | E24: =E23/E11 -> 146.11 | F24: =F23/F11 -> 151.28 | G24: =G23/G11 -> 155.84 | H24: =H23/H11 -> 162.55 | I24: =I23/I11 -> 168.48 | J24: =J23/J11 -> 174.7 | K24: =K23/K11 -> 171.74 | ... P24: =P23/P11 -> 160.04279
C25: RevPAR | D25: =D23/D10 -> 79.53 | E25: =E23/E10 -> 84.7438 | F25: =F23/F10 -> 98.332 | G25: =G23/G10 -> 109.088 | H25: =H23/H10 -> 120.287 | I25: =I23/I10 -> 131.4144 | J25: =J23/J10 -> 146.748 | K25: =K23/K10 -> 140.8268 | ... P25: =P23/P10 -> 110.81977
C28: Variable and operating costs
C29: Housekeeping hours per occupied room | D29: =INDEX(Assumptions!$J$8:$J$19,MATCH(D$5,Assumptions!$D$8:$D$19,0)) -> 0.56 | E29: =INDEX(Assumptions!$J$8:$J$19,MATCH(E$5,Assumptions!$D$8:$D$19,0)) -> 0.55 | F29: =INDEX(Assumptions!$J$8:$J$19,MATCH(F$5,Assumptions!$D$8:$D$19,0)) -> 0.54 | G29: =INDEX(Assumptions!$J$8:$J$19,MATCH(G$5,Assumptions!$D$8:$D$19,0)) -> 0.53 | H29: =INDEX(Assumptions!$J$8:$J$19,MATCH(H$5,Assumptions!$D$8:$D$19,0)) -> 0.52 | I29: =INDEX(Assumptions!$J$8:$J$19,MATCH(I$5,Assumptions!$D$8:$D$19,0)) -> 0.51 | J29: =INDEX(Assumptions!$J$8:$J$19,MATCH(J$5,Assumptions!$D$8:$D$19,0)) -> 0.5 | K29: =INDEX(Assumptions!$J$8:$J$19,MATCH(K$5,Assumptions!$D$8:$D$19,0)) -> 0.5 | ... O29: =INDEX(Assumptions!$J$8:$J$19,MATCH(O$5,Assumptions!$D$8:$D$19,0)) -> 0.56 | P29: =P31/P11 -> 0.52799122
C30: Loaded housekeeping wage per hour | D30: =INDEX(Assumptions!$K$8:$K$19,MATCH(D$5,Assumptions!$D$8:$D$19,0)) -> 22 | E30: =INDEX(Assumptions!$K$8:$K$19,MATCH(E$5,Assumptions!$D$8:$D$19,0)) -> 22 | F30: =INDEX(Assumptions!$K$8:$K$19,MATCH(F$5,Assumptions!$D$8:$D$19,0)) -> 22 | G30: =INDEX(Assumptions!$K$8:$K$19,MATCH(G$5,Assumptions!$D$8:$D$19,0)) -> 22 | H30: =INDEX(Assumptions!$K$8:$K$19,MATCH(H$5,Assumptions!$D$8:$D$19,0)) -> 22 | I30: =INDEX(Assumptions!$K$8:$K$19,MATCH(I$5,Assumptions!$D$8:$D$19,0)) -> 22 | J30: =INDEX(Assumptions!$K$8:$K$19,MATCH(J$5,Assumptions!$D$8:$D$19,0)) -> 22.75 | K30: =INDEX(Assumptions!$K$8:$K$19,MATCH(K$5,Assumptions!$D$8:$D$19,0)) -> 22.75 | ... O30: =INDEX(Assumptions!$K$8:$K$19,MATCH(O$5,Assumptions!$D$8:$D$19,0)) -> 22.75 | P30: =P32/P31 -> 22.388311
C31: Housekeeping hours | D31: =D11*D29 -> 954.8 | E31: =E11*E29 -> 893.2 | F31: =F11*F29 -> 1088.1 | G31: =G11*G29 -> 1113 | H31: =H11*H29 -> 1192.88 | I31: =I11*I29 -> 1193.4 | J31: =J11*J29 -> 1302 | K31: =K11*K29 -> 1271 | ... O31: =O11*O29 -> 1024.24 | P31: =SUM(D31:O31) -> 13344.45
C32: Housekeeping payroll | D32: =D31*D30 -> 21005.6 | E32: =E31*E30 -> 19650.4 | F32: =F31*F30 -> 23938.2 | G32: =G31*G30 -> 24486 | H32: =H31*H30 -> 26243.36 | I32: =I31*I30 -> 26254.8 | J32: =J31*J30 -> 29620.5 | K32: =K31*K30 -> 28915.25 | ... O32: =O31*O30 -> 23301.46 | P32: =SUM(D32:O32) -> 298759.7
C33: Guest-service cost per occupied room | D33: =INDEX(Assumptions!$L$8:$L$19,MATCH(D$5,Assumptions!$D$8:$D$19,0)) -> 18.5 | E33: =INDEX(Assumptions!$L$8:$L$19,MATCH(E$5,Assumptions!$D$8:$D$19,0)) -> 18.7 | F33: =INDEX(Assumptions!$L$8:$L$19,MATCH(F$5,Assumptions!$D$8:$D$19,0)) -> 19 | G33: =INDEX(Assumptions!$L$8:$L$19,MATCH(G$5,Assumptions!$D$8:$D$19,0)) -> 19.2 | H33: =INDEX(Assumptions!$L$8:$L$19,MATCH(H$5,Assumptions!$D$8:$D$19,0)) -> 19.5 | I33: =INDEX(Assumptions!$L$8:$L$19,MATCH(I$5,Assumptions!$D$8:$D$19,0)) -> 19.8 | J33: =INDEX(Assumptions!$L$8:$L$19,MATCH(J$5,Assumptions!$D$8:$D$19,0)) -> 20 | K33: =INDEX(Assumptions!$L$8:$L$19,MATCH(K$5,Assumptions!$D$8:$D$19,0)) -> 20 | ... O33: =INDEX(Assumptions!$L$8:$L$19,MATCH(O$5,Assumptions!$D$8:$D$19,0)) -> 19.2 | P33: =P34/P11 -> 19.414006
C34: Guest-service expense | D34: =D11*D33 -> 31542.5 | E34: =E11*E33 -> 30368.8 | F34: =F11*F33 -> 38285 | G34: =G11*G33 -> 40320 | H34: =H11*H33 -> 44733 | I34: =I11*I33 -> 46332 | J34: =J11*J33 -> 52080 | K34: =K11*K33 -> 50840 | ... O34: =O11*O33 -> 35116.8 | P34: =SUM(D34:O34) -> 490669.6
C35: Distribution fee rate | D35: =INDEX(Assumptions!$M$8:$M$19,MATCH(D$5,Assumptions!$D$8:$D$19,0)) -> 0.04 | E35: =INDEX(Assumptions!$M$8:$M$19,MATCH(E$5,Assumptions!$D$8:$D$19,0)) -> 0.04 | F35: =INDEX(Assumptions!$M$8:$M$19,MATCH(F$5,Assumptions!$D$8:$D$19,0)) -> 0.04 | G35: =INDEX(Assumptions!$M$8:$M$19,MATCH(G$5,Assumptions!$D$8:$D$19,0)) -> 0.04 | H35: =INDEX(Assumptions!$M$8:$M$19,MATCH(H$5,Assumptions!$D$8:$D$19,0)) -> 0.04 | I35: =INDEX(Assumptions!$M$8:$M$19,MATCH(I$5,Assumptions!$D$8:$D$19,0)) -> 0.04 | J35: =INDEX(Assumptions!$M$8:$M$19,MATCH(J$5,Assumptions!$D$8:$D$19,0)) -> 0.04 | K35: =INDEX(Assumptions!$M$8:$M$19,MATCH(K$5,Assumptions!$D$8:$D$19,0)) -> 0.04 | ... O35: =INDEX(Assumptions!$M$8:$M$19,MATCH(O$5,Assumptions!$D$8:$D$19,0)) -> 0.04 | P35: =P36/P23 -> 0.04
C36: Distribution and payment expense | D36: =D23*D35 -> 9861.72 | E36: =E23*E35 -> 9491.3056 | F36: =F23*F35 -> 12193.168 | G36: =G23*G35 -> 13090.56 | H36: =H23*H35 -> 14915.588 | I36: =I23*I35 -> 15769.728 | J36: =J23*J35 -> 18196.752 | K36: =K23*K35 -> 17462.523 | ... O36: =O23*O35 -> 11336.874 | P36: =SUM(D36:O36) -> 161796.86
C39: Fixed costs
C40: Fixed staff FTE | D40: =INDEX(Assumptions!$N$8:$N$19,MATCH(D$5,Assumptions!$D$8:$D$19,0)) -> 5 | E40: =INDEX(Assumptions!$N$8:$N$19,MATCH(E$5,Assumptions!$D$8:$D$19,0)) -> 5 | F40: =INDEX(Assumptions!$N$8:$N$19,MATCH(F$5,Assumptions!$D$8:$D$19,0)) -> 5 | G40: =INDEX(Assumptions!$N$8:$N$19,MATCH(G$5,Assumptions!$D$8:$D$19,0)) -> 5 | H40: =INDEX(Assumptions!$N$8:$N$19,MATCH(H$5,Assumptions!$D$8:$D$19,0)) -> 5 | I40: =INDEX(Assumptions!$N$8:$N$19,MATCH(I$5,Assumptions!$D$8:$D$19,0)) -> 5 | J40: =INDEX(Assumptions!$N$8:$N$19,MATCH(J$5,Assumptions!$D$8:$D$19,0)) -> 5 | K40: =INDEX(Assumptions!$N$8:$N$19,MATCH(K$5,Assumptions!$D$8:$D$19,0)) -> 5 | ... O40: =INDEX(Assumptions!$N$8:$N$19,MATCH(O$5,Assumptions!$D$8:$D$19,0)) -> 5 | P40: =AVERAGE(D40:O40) -> 5
C41: Fixed staff loaded cost per FTE | D41: =INDEX(Assumptions!$O$8:$O$19,MATCH(D$5,Assumptions!$D$8:$D$19,0)) -> 6000 | E41: =INDEX(Assumptions!$O$8:$O$19,MATCH(E$5,Assumptions!$D$8:$D$19,0)) -> 6000 | F41: =INDEX(Assumptions!$O$8:$O$19,MATCH(F$5,Assumptions!$D$8:$D$19,0)) -> 6000 | G41: =INDEX(Assumptions!$O$8:$O$19,MATCH(G$5,Assumptions!$D$8:$D$19,0)) -> 6000 | H41: =INDEX(Assumptions!$O$8:$O$19,MATCH(H$5,Assumptions!$D$8:$D$19,0)) -> 6000 | I41: =INDEX(Assumptions!$O$8:$O$19,MATCH(I$5,Assumptions!$D$8:$D$19,0)) -> 6000 | J41: =INDEX(Assumptions!$O$8:$O$19,MATCH(J$5,Assumptions!$D$8:$D$19,0)) -> 6120 | K41: =INDEX(Assumptions!$O$8:$O$19,MATCH(K$5,Assumptions!$D$8:$D$19,0)) -> 6120 | ... O41: =INDEX(Assumptions!$O$8:$O$19,MATCH(O$5,Assumptions!$D$8:$D$19,0)) -> 6120 | P41: =P42/SUM(D40:O40) -> 6060
C42: Fixed staff payroll | D42: =D40*D41 -> 30000 | E42: =E40*E41 -> 30000 | F42: =F40*F41 -> 30000 | G42: =G40*G41 -> 30000 | H42: =H40*H41 -> 30000 | I42: =I40*I41 -> 30000 | J42: =J40*J41 -> 30600 | K42: =K40*K41 -> 30600 | ... O42: =O40*O41 -> 30600 | P42: =SUM(D42:O42) -> 363600
C43: Rent | D43: =INDEX(Assumptions!$P$8:$P$19,MATCH(D$5,Assumptions!$D$8:$D$19,0)) -> 78000 | E43: =INDEX(Assumptions!$P$8:$P$19,MATCH(E$5,Assumptions!$D$8:$D$19,0)) -> 78000 | F43: =INDEX(Assumptions!$P$8:$P$19,MATCH(F$5,Assumptions!$D$8:$D$19,0)) -> 78000 | G43: =INDEX(Assumptions!$P$8:$P$19,MATCH(G$5,Assumptions!$D$8:$D$19,0)) -> 78000 | H43: =INDEX(Assumptions!$P$8:$P$19,MATCH(H$5,Assumptions!$D$8:$D$19,0)) -> 78000 | I43: =INDEX(Assumptions!$P$8:$P$19,MATCH(I$5,Assumptions!$D$8:$D$19,0)) -> 78000 | J43: =INDEX(Assumptions!$P$8:$P$19,MATCH(J$5,Assumptions!$D$8:$D$19,0)) -> 78000 | K43: =INDEX(Assumptions!$P$8:$P$19,MATCH(K$5,Assumptions!$D$8:$D$19,0)) -> 78000 | ... O43: =INDEX(Assumptions!$P$8:$P$19,MATCH(O$5,Assumptions!$D$8:$D$19,0)) -> 78000 | P43: =SUM(D43:O43) -> 936000
C44: Property overhead | D44: =INDEX(Assumptions!$Q$8:$Q$19,MATCH(D$5,Assumptions!$D$8:$D$19,0)) -> 28000 | E44: =INDEX(Assumptions!$Q$8:$Q$19,MATCH(E$5,Assumptions!$D$8:$D$19,0)) -> 28100 | F44: =INDEX(Assumptions!$Q$8:$Q$19,MATCH(F$5,Assumptions!$D$8:$D$19,0)) -> 28500 | G44: =INDEX(Assumptions!$Q$8:$Q$19,MATCH(G$5,Assumptions!$D$8:$D$19,0)) -> 28600 | H44: =INDEX(Assumptions!$Q$8:$Q$19,MATCH(H$5,Assumptions!$D$8:$D$19,0)) -> 28900 | I44: =INDEX(Assumptions!$Q$8:$Q$19,MATCH(I$5,Assumptions!$D$8:$D$19,0)) -> 29200 | J44: =INDEX(Assumptions!$Q$8:$Q$19,MATCH(J$5,Assumptions!$D$8:$D$19,0)) -> 29800 | K44: =INDEX(Assumptions!$Q$8:$Q$19,MATCH(K$5,Assumptions!$D$8:$D$19,0)) -> 30000 | ... O44: =INDEX(Assumptions!$Q$8:$Q$19,MATCH(O$5,Assumptions!$D$8:$D$19,0)) -> 29000 | P44: =SUM(D44:O44) -> 347300
C45: Marketing | D45: =INDEX(Assumptions!$R$8:$R$19,MATCH(D$5,Assumptions!$D$8:$D$19,0)) -> 10000 | E45: =INDEX(Assumptions!$R$8:$R$19,MATCH(E$5,Assumptions!$D$8:$D$19,0)) -> 9000 | F45: =INDEX(Assumptions!$R$8:$R$19,MATCH(F$5,Assumptions!$D$8:$D$19,0)) -> 11000 | G45: =INDEX(Assumptions!$R$8:$R$19,MATCH(G$5,Assumptions!$D$8:$D$19,0)) -> 13000 | H45: =INDEX(Assumptions!$R$8:$R$19,MATCH(H$5,Assumptions!$D$8:$D$19,0)) -> 14000 | I45: =INDEX(Assumptions!$R$8:$R$19,MATCH(I$5,Assumptions!$D$8:$D$19,0)) -> 24000 | J45: =INDEX(Assumptions!$R$8:$R$19,MATCH(J$5,Assumptions!$D$8:$D$19,0)) -> 18000 | K45: =INDEX(Assumptions!$R$8:$R$19,MATCH(K$5,Assumptions!$D$8:$D$19,0)) -> 15000 | ... O45: =INDEX(Assumptions!$R$8:$R$19,MATCH(O$5,Assumptions!$D$8:$D$19,0)) -> 16000 | P45: =SUM(D45:O45) -> 167000
C48: Profitability
C49: Total operating costs | D49: =SUM(D32,D34,D36,D42:D45) -> 208409.82 | E49: =SUM(E32,E34,E36,E42:E45) -> 204610.51 | F49: =SUM(F32,F34,F36,F42:F45) -> 221916.37 | G49: =SUM(G32,G34,G36,G42:G45) -> 227496.56 | H49: =SUM(H32,H34,H36,H42:H45) -> 236791.95 | I49: =SUM(I32,I34,I36,I42:I45) -> 249556.53 | J49: =SUM(J32,J34,J36,J42:J45) -> 256297.25 | K49: =SUM(K32,K34,K36,K42:K45) -> 250817.77 | ... O49: =SUM(O32,O34,O36,O42:O45) -> 223355.13 | P49: =SUM(D49:O49) -> 2765126.2
C50: Property operating contribution | D50: =D23-D49 -> 38133.18 | E50: =E23-E49 -> 32672.134 | F50: =F23-F49 -> 82912.832 | G50: =G23-G49 -> 99767.44 | H50: =H23-H49 -> 136097.75 | I50: =I23-I49 -> 144686.67 | J50: =J23-J49 -> 198621.55 | K50: =K23-K49 -> 185745.31 | ... O50: =O23-O49 -> 60066.706 | P50: =SUM(D50:O50) -> 1279795.4
...

Sheet Forecast
C2: 2026 RF1 — Actuals Through June 2026
C3: January–June recorded actuals plus a July–December driver-based forecast. Base is the official working reforecast; Upside and Downside are bounded sensitivities.
C5: Forecast version | D5: 2026 RF1 | F5: Case version | G5: v1.0 | I5: Cutoff | J5: 46211 | L5: Actuals | M5: Jan–Jun 2026 | O5: Forecast | P5: Jul–Dec 2026 | R5: Official case | S5: Base
C7: Full-year scenario summary | L7: Principal H2 driver differences
C8: Metric | D8: Approved Budget | E8: Base RF1 | F8: Base vs Budget | G8: Upside | H8: Upside vs Base | I8: Downside | J8: Downside vs Base | L8: Driver | M8: Base | N8: Upside | O8: Δ vs Base | P8: Downside | Q8: Δ vs Base
C9: Occupied room nights | D9: =Budget!P11 -> 25274 | E9: =P32 -> 24518 | F9: =E9-D9 -> -756 | G9: =P80 -> 24850 | H9: =G9-E9 -> 332 | I9: =P128 -> 23919 | J9: =I9-E9 -> -599 | L9: H2 occupied room nights | M9: =SUM(J32:O32) -> 12980 | N9: =SUM(J80:O80) -> 13312 | O9: =N9-M9 -> 332 | P9: =SUM(J128:O128) -> 12381 | Q9: =P9-M9 -> -599
C10: Occupancy | D10: =Budget!P12 -> 0.69243836 | E10: =P33 -> 0.67172603 | F10: =E10-D10 -> -0.020712329 | G10: =P81 -> 0.68082192 | H10: =G10-E10 -> 0.0090958904 | I10: =P129 -> 0.65531507 | J10: =I10-E10 -> -0.016410959 | L10: H2 corporate share | M10: =SUM(J36:O36)/SUM(J32:O32) -> 0.39694646 | N10: =SUM(J84:O84)/SUM(J80:O80) -> 0.40205116 | O10: =N10-M10 -> 0.0051047008 | P10: =SUM(J132:O132)/SUM(J128:O128) -> 0.38202367 | Q10: =P10-M10 -> -0.014922791
C11: Corporate share | D11: =Budget!P13 -> 0.35292395 | E11: =P34 -> 0.39474529 | F11: =E11-D11 -> 0.041821336 | G11: =P82 -> 0.39750926 | H11: =G11-E11 -> 0.0027639664 | I11: =P130 -> 0.3869658 | J11: =I11-E11 -> -0.0077794879 | L11: H2 Retail ADR | M11: =SUM(J41:O41)/SUM(J35:O35) -> 174.00368 | N11: =SUM(J89:O89)/SUM(J83:O83) -> 175.78525 | O11: =N11-M11 -> 1.7815683 | P11: =SUM(J137:O137)/SUM(J131:O131) -> 170.5835 | Q11: =P11-M11 -> -3.4201862
C12: Total room revenue | D12: =Budget!P23 -> 4044921.6 | E12: =P43 -> 3903659.4 | F12: =E12-D12 -> -141262.21 | G12: =P91 -> 3974207.9 | H12: =G12-E12 -> 70548.523 | I12: =P139 -> 3777975 | J12: =I12-E12 -> -125684.34 | L12: H2 Corporate ADR | M12: =SUM(J42:O42)/SUM(J36:O36) -> 146.87664 | N12: =SUM(J90:O90)/SUM(J84:O84) -> 147.6271 | O12: =N12-M12 -> 0.75046341 | P12: =SUM(J138:O138)/SUM(J132:O132) -> 145.44959 | Q12: =P12-M12 -> -1.4270499
C13: Blended ADR | D13: =Budget!P24 -> 160.04279 | E13: =P44 -> 159.21606 | F13: =E13-D13 -> -0.82673363 | G13: =P92 -> 159.92788 | H13: =G13-E13 -> 0.71182256 | I13: =P140 -> 157.9487 | J13: =I13-E13 -> -1.2673572 | L13: H2 housekeeping hours / occupied room | M13: =SUM(J50:O50)/SUM(J32:O32) -> 0.54282897 | N13: =SUM(J98:O98)/SUM(J80:O80) -> 0.53143104 | O13: =N13-M13 -> -0.011397928 | P13: =SUM(J146:O146)/SUM(J128:O128) -> 0.55839351 | Q13: =P13-M13 -> 0.015564539
C14: RevPAR | D14: =Budget!P25 -> 110.81977 | E14: =P45 -> 106.94957 | F14: =E14-D14 -> -3.8701975 | G14: =P93 -> 108.88241 | H14: =G14-E14 -> 1.9328362 | I14: =P141 -> 103.50617 | J14: =I14-E14 -> -3.4434065
C15: Total operating costs | D15: =Budget!P49 -> 2765126.2 | E15: =P66 -> 2766112.2 | F15: =E15-D15 -> 986.0292 | G15: =P114 -> 2776133.9 | H15: =G15-E15 -> 10021.733 | I15: =P162 -> 2746264.6 | J15: =I15-E15 -> -19847.636
C16: Property operating contribution | D16: =Budget!P50 -> 1279795.4 | E16: =P67 -> 1137547.2 | F16: =E16-D16 -> -142248.24 | G16: =P115 -> 1198074 | H16: =G16-E16 -> 60526.789 | I16: =P163 -> 1031710.5 | J16: =I16-E16 -> -105836.7
C17: Contribution margin | D17: =Budget!P51 -> 0.31639561 | E17: =P68 -> 0.29140534 | F17: =E17-D17 -> -0.024990268 | G17: =P116 -> 0.30146233 | H17: =G17-E17 -> 0.010056991 | I17: =P164 -> 0.27308557 | J17: =I17-E17 -> -0.018319765
C19: Forecast accuracy: Phase 3 actual-versus-budget analysis is the available evidence about approved-plan performance. RF1 accuracy cannot be evaluated until later actual results exist.
C20: Scenario ranges are decision-support cases, not confidence intervals, and no probability weighting is used.
C22: Detailed scenarios — January–June Actual (A), July–December Forecast (F)
C24: Base — 2026 RF1
C25: Period type | D25: A | E25: A | F25: A | G25: A | H25: A | I25: A | J25: F | K25: F | L25: F | M25: F | N25: F | O25: F | P25: FY2026 | Q25: Approved Budget | R25: Variance | S25: Variance % / pp
C26: Month | D26: 46023 | E26: 46054 | F26: 46082 | G26: 46113 | H26: 46143 | I26: 46174 | J26: 46204 | K26: 46235 | L26: 46266 | M26: 46296 | N26: 46327 | O26: 46357 | P26: FY2026 | Q26: Approved Budget | R26: Variance | S26: Variance % / pp
C27: Actual costs remain recorded facts; forecast costs use visible assumptions.
C28: Operating drivers
C29: Rooms available | D29: =Budget!D8 -> 100 | E29: =Budget!E8 -> 100 | F29: =Budget!F8 -> 100 | G29: =Budget!G8 -> 100 | H29: =Budget!H8 -> 100 | I29: =Budget!I8 -> 100 | J29: =Assumptions!F41 -> 100 | K29: =Assumptions!G41 -> 100 | L29: =Assumptions!H41 -> 100 | M29: =Assumptions!I41 -> 100 | N29: =Assumptions!J41 -> 100 | O29: =Assumptions!K41 -> 100 | P29: =AVERAGE(D29:O29) -> 100 | Q29: =Budget!P8 -> 100 | R29: =P29-Q29 -> 0 | S29: =IF(Q29=0,"n.a.",R29/ABS(Q29)) -> 0
C30: Calendar days | D30: =DATE(YEAR(D$26),MONTH(D$26)+1,1)-D$26 -> 31 | E30: =DATE(YEAR(E$26),MONTH(E$26)+1,1)-E$26 -> 28 | F30: =DATE(YEAR(F$26),MONTH(F$26)+1,1)-F$26 -> 31 | G30: =DATE(YEAR(G$26),MONTH(G$26)+1,1)-G$26 -> 30 | H30: =DATE(YEAR(H$26),MONTH(H$26)+1,1)-H$26 -> 31 | I30: =DATE(YEAR(I$26),MONTH(I$26)+1,1)-I$26 -> 30 | J30: =DATE(YEAR(J$26),MONTH(J$26)+1,1)-J$26 -> 31 | K30: =DATE(YEAR(K$26),MONTH(K$26)+1,1)-K$26 -> 31 | ... O30: =DATE(YEAR(O$26),MONTH(O$26)+1,1)-O$26 -> 31 | P30: =SUM(D30:O30) -> 365 | Q30: =Budget!P9 -> 365 | R30: =P30-Q30 -> 0 | S30: =IF(Q30=0,"n.a.",R30/ABS(Q30)) -> 0
C31: Available room nights | D31: =D29*D30 -> 3100 | E31: =E29*E30 -> 2800 | F31: =F29*F30 -> 3100 | G31: =G29*G30 -> 3000 | H31: =H29*H30 -> 3100 | I31: =I29*I30 -> 3000 | J31: =J29*J30 -> 3100 | K31: =K29*K30 -> 3100 | ... O31: =O29*O30 -> 3100 | P31: =SUM(D31:O31) -> 36500 | Q31: =Budget!P10 -> 36500 | R31: =P31-Q31 -> 0 | S31: =IF(Q31=0,"n.a.",R31/ABS(Q31)) -> 0
C32: Occupied room nights | D32: =SUM(D35:D36) -> 1658 | E32: =SUM(E35:E36) -> 1604 | F32: =SUM(F35:F36) -> 1922 | G32: =SUM(G35:G36) -> 1950 | H32: =SUM(H35:H36) -> 2139 | I32: =SUM(I35:I36) -> 2265 | J32: =Assumptions!F42 -> 2552 | K32: =Assumptions!G42 -> 2491 | L32: =Assumptions!H42 -> 2146 | M32: =Assumptions!I42 -> 2168 | N32: =Assumptions!J42 -> 1812 | O32: =Assumptions!K42 -> 1811 | P32: =SUM(D32:O32) -> 24518 | Q32: =Budget!P11 -> 25274 | R32: =P32-Q32 -> -756 | S32: =IF(Q32=0,"n.a.",R32/ABS(Q32)) -> -0.029912163
C33: Occupancy | D33: =D32/D31 -> 0.53483871 | E33: =E32/E31 -> 0.57285714 | F33: =F32/F31 -> 0.62 | G33: =G32/G31 -> 0.65 | H33: =H32/H31 -> 0.69 | I33: =I32/I31 -> 0.755 | J33: =J32/J31 -> 0.82322581 | K33: =K32/K31 -> 0.80354839 | ... P33: =P32/P31 -> 0.67172603 | Q33: =Budget!P12 -> 0.69243836 | R33: =P33-Q33 -> -0.020712329 | S33: =R33 -> -0.020712329
C34: Corporate share | D34: =D36/D32 -> 0.31001206 | E34: =E36/E32 -> 0.3298005 | F34: =F36/F32 -> 0.3798127 | G34: =G36/G32 -> 0.43025641 | H34: =H36/H32 -> 0.45021038 | I34: =I36/I32 -> 0.41986755 | J34: =Assumptions!F43 -> 0.41 | K34: =Assumptions!G43 -> 0.42 | L34: =Assumptions!H43 -> 0.43 | M34: =Assumptions!I43 -> 0.405 | N34: =Assumptions!J43 -> 0.36 | O34: =Assumptions!K43 -> 0.335 | P34: =P36/P32 -> 0.39474529 | Q34: =Budget!P13 -> 0.35292395 | R34: =P34-Q34 -> 0.041821336 | S34: =R34 -> 0.041821336
C35: Retail room nights | D35: =SUMIFS(Data!$F$158:$F$193,Data!$D$158:$D$193,D$26,Data!$E$158:$E$193,"Retail/Leisure") -> 1144 | E35: =SUMIFS(Data!$F$158:$F$193,Data!$D$158:$D$193,E$26,Data!$E$158:$E$193,"Retail/Leisure") -> 1075 | F35: =SUMIFS(Data!$F$158:$F$193,Data!$D$158:$D$193,F$26,Data!$E$158:$E$193,"Retail/Leisure") -> 1192 | G35: =SUMIFS(Data!$F$158:$F$193,Data!$D$158:$D$193,G$26,Data!$E$158:$E$193,"Retail/Leisure") -> 1111 | H35: =SUMIFS(Data!$F$158:$F$193,Data!$D$158:$D$193,H$26,Data!$E$158:$E$193,"Retail/Leisure") -> 1176 | I35: =SUMIFS(Data!$F$158:$F$193,Data!$D$158:$D$193,I$26,Data!$E$158:$E$193,"Retail/Leisure") -> 1314 | J35: =J32-J36 -> 1505.68 | K35: =K32-K36 -> 1444.78 | L35: =L32-L36 -> 1223.22 | M35: =M32-M36 -> 1289.96 | N35: =N32-N36 -> 1159.68 | O35: =O32-O36 -> 1204.315 | P35: =SUM(D35:O35) -> 14839.635 | Q35: =Budget!P14 -> 16354.2 | R35: =P35-Q35 -> -1514.565 | S35: =IF(Q35=0,"n.a.",R35/ABS(Q35)) -> -0.092610155
C36: Corporate room nights | D36: =SUMIFS(Data!$F$158:$F$193,Data!$D$158:$D$193,D$26,Data!$E$158:$E$193,"Negotiated Corporate") -> 514 | E36: =SUMIFS(Data!$F$158:$F$193,Data!$D$158:$D$193,E$26,Data!$E$158:$E$193,"Negotiated Corporate") -> 529 | F36: =SUMIFS(Data!$F$158:$F$193,Data!$D$158:$D$193,F$26,Data!$E$158:$E$193,"Negotiated Corporate") -> 730 | G36: =SUMIFS(Data!$F$158:$F$193,Data!$D$158:$D$193,G$26,Data!$E$158:$E$193,"Negotiated Corporate") -> 839 | H36: =SUMIFS(Data!$F$158:$F$193,Data!$D$158:$D$193,H$26,Data!$E$158:$E$193,"Negotiated Corporate") -> 963 | I36: =SUMIFS(Data!$F$158:$F$193,Data!$D$158:$D$193,I$26,Data!$E$158:$E$193,"Negotiated Corporate") -> 951 | J36: =J32*J34 -> 1046.32 | K36: =K32*K34 -> 1046.22 | L36: =L32*L34 -> 922.78 | M36: =M32*M34 -> 878.04 | N36: =N32*N34 -> 652.32 | O36: =O32*O34 -> 606.685 | P36: =SUM(D36:O36) -> 9678.365 | Q36: =Budget!P15 -> 8919.8 | R36: =P36-Q36 -> 758.565 | S36: =IF(Q36=0,"n.a.",R36/ABS(Q36)) -> 0.085042826
C37: Retail ADR | D37: =D41/D35 -> 151 | E37: =E41/E35 -> 153 | F37: =F41/F35 -> 158.5 | G37: =G41/G35 -> 164 | H37: =H41/H35 -> 171 | I37: =I41/I35 -> 181 | J37: =Assumptions!F44 -> 188 | K37: =Assumptions!G44 -> 185 | L37: =Assumptions!H44 -> 175 | M37: =Assumptions!I44 -> 170 | N37: =Assumptions!J44 -> 158 | O37: =Assumptions!K44 -> 162 | P37: =P41/P35 -> 169.09596 | Q37: =Budget!P16 -> 168.99758 | R37: =P37-Q37 -> 0.098374178 | S37: =IF(Q37=0,"n.a.",R37/ABS(Q37)) -> 0.00058210405
C38: Corporate ADR | D38: =D42/D36 -> 132.5 | E38: =E42/E36 -> 133 | F38: =F42/F36 -> 137.5 | G38: =G42/G36 -> 140.5 | H38: =H42/H36 -> 145 | I38: =I42/I36 -> 148.5 | J38: =Assumptions!F45 -> 153.5 | K38: =Assumptions!G45 -> 151.5 | L38: =Assumptions!H45 -> 146.5 | M38: =Assumptions!I45 -> 144.5 | N38: =Assumptions!J45 -> 138.5 | O38: =Assumptions!K45 -> 140.5 | P38: =P42/P36 -> 144.06742 | Q38: =Budget!P17 -> 143.62444 | R38: =P38-Q38 -> 0.44297866 | S38: =IF(Q38=0,"n.a.",R38/ABS(Q38)) -> 0.0030842847
C40: Revenue
C41: Retail room revenue | D41: =SUMIFS(Data!$G$158:$G$193,Data!$D$158:$D$193,D$26,Data!$E$158:$E$193,"Retail/Leisure") -> 172744 | E41: =SUMIFS(Data!$G$158:$G$193,Data!$D$158:$D$193,E$26,Data!$E$158:$E$193,"Retail/Leisure") -> 164475 | F41: =SUMIFS(Data!$G$158:$G$193,Data!$D$158:$D$193,F$26,Data!$E$158:$E$193,"Retail/Leisure") -> 188932 | G41: =SUMIFS(Data!$G$158:$G$193,Data!$D$158:$D$193,G$26,Data!$E$158:$E$193,"Retail/Leisure") -> 182204 | H41: =SUMIFS(Data!$G$158:$G$193,Data!$D$158:$D$193,H$26,Data!$E$158:$E$193,"Retail/Leisure") -> 201096 | I41: =SUMIFS(Data!$G$158:$G$193,Data!$D$158:$D$193,I$26,Data!$E$158:$E$193,"Retail/Leisure") -> 237834 | J41: =J35*J37 -> 283067.84 | K41: =K35*K37 -> 267284.3 | L41: =L35*L37 -> 214063.5 | M41: =M35*M37 -> 219293.2 | N41: =N35*N37 -> 183229.44 | O41: =O35*O37 -> 195099.03 | P41: =SUM(D41:O41) -> 2509322.3 | Q41: =Budget!P21 -> 2763820.3 | R41: =P41-Q41 -> -254497.99 | S41: =IF(Q41=0,"n.a.",R41/ABS(Q41)) -> -0.09208196
C42: Corporate room revenue | D42: =SUMIFS(Data!$G$158:$G$193,Data!$D$158:$D$193,D$26,Data!$E$158:$E$193,"Negotiated Corporate") -> 68105 | E42: =SUMIFS(Data!$G$158:$G$193,Data!$D$158:$D$193,E$26,Data!$E$158:$E$193,"Negotiated Corporate") -> 70357 | F42: =SUMIFS(Data!$G$158:$G$193,Data!$D$158:$D$193,F$26,Data!$E$158:$E$193,"Negotiated Corporate") -> 100375 | G42: =SUMIFS(Data!$G$158:$G$193,Data!$D$158:$D$193,G$26,Data!$E$158:$E$193,"Negotiated Corporate") -> 117879.5 | H42: =SUMIFS(Data!$G$158:$G$193,Data!$D$158:$D$193,H$26,Data!$E$158:$E$193,"Negotiated Corporate") -> 139635 | I42: =SUMIFS(Data!$G$158:$G$193,Data!$D$158:$D$193,I$26,Data!$E$158:$E$193,"Negotiated Corporate") -> 141223.5 | J42: =J36*J38 -> 160610.12 | K42: =K36*K38 -> 158502.33 | L42: =L36*L38 -> 135187.27 | M42: =M36*M38 -> 126876.78 | N42: =N36*N38 -> 90346.32 | O42: =O36*O38 -> 85239.243 | P42: =SUM(D42:O42) -> 1394337.1 | Q42: =Budget!P22 -> 1281101.3 | R42: =P42-Q42 -> 113235.78 | S42: =IF(Q42=0,"n.a.",R42/ABS(Q42)) -> 0.088389407
C43: Total room revenue | D43: =SUM(D41:D42) -> 240849 | E43: =SUM(E41:E42) -> 234832 | F43: =SUM(F41:F42) -> 289307 | G43: =SUM(G41:G42) -> 300083.5 | H43: =SUM(H41:H42) -> 340731 | I43: =SUM(I41:I42) -> 379057.5 | J43: =SUM(J41:J42) -> 443677.96 | K43: =SUM(K41:K42) -> 425786.63 | ... O43: =SUM(O41:O42) -> 280338.27 | P43: =SUM(D43:O43) -> 3903659.4 | Q43: =Budget!P23 -> 4044921.6 | R43: =P43-Q43 -> -141262.21 | S43: =IF(Q43=0,"n.a.",R43/ABS(Q43)) -> -0.034923349
C44: Blended ADR | D44: =D43/D32 -> 145.26478 | E44: =E43/E32 -> 146.40399 | F44: =F43/F32 -> 150.52393 | G44: =G43/G32 -> 153.88897 | H44: =H43/H32 -> 159.29453 | I44: =I43/I32 -> 167.3543 | J44: =J43/J32 -> 173.855 | K44: =K43/K32 -> 170.93 | ... P44: =P43/P32 -> 159.21606 | Q44: =Budget!P24 -> 160.04279 | R44: =P44-Q44 -> -0.82673363 | S44: =IF(Q44=0,"n.a.",R44/ABS(Q44)) -> -0.0051657035
C45: RevPAR | D45: =D43/D31 -> 77.693226 | E45: =E43/E31 -> 83.868571 | F45: =F43/F31 -> 93.324839 | G45: =G43/G31 -> 100.02783 | H45: =H43/H31 -> 109.91323 | I45: =I43/I31 -> 126.3525 | J45: =J43/J31 -> 143.12192 | K45: =K43/K31 -> 137.35053 | ... P45: =P43/P31 -> 106.94957 | Q45: =Budget!P25 -> 110.81977 | R45: =P45-Q45 -> -3.8701975 | S45: =IF(Q45=0,"n.a.",R45/ABS(Q45)) -> -0.034923349
C47: Variable and operating costs
C48: Housekeeping hours per occupied room | D48: =D50/D32 -> 0.57 | E48: =E50/E32 -> 0.55 | F48: =F50/F32 -> 0.56 | G48: =G50/G32 -> 0.62 | H48: =H50/H32 -> 0.6 | I48: =I50/I32 -> 0.56 | J48: =Assumptions!F46 -> 0.55 | K48: =Assumptions!G46 -> 0.54 | L48: =Assumptions!H46 -> 0.53 | M48: =Assumptions!I46 -> 0.53 | N48: =Assumptions!J46 -> 0.55 | O48: =Assumptions!K46 -> 0.56 | P48: =P50/P32 -> 0.55919325 | Q48: =Budget!P29 -> 0.52799122 | R48: =P48-Q48 -> 0.03120203 | S48: =IF(Q48=0,"n.a.",R48/ABS(Q48)) -> 0.059095736
...

Sheet Variance
C2: Actual performance and variance attribution
C3: January–June 2026 actuals compared with the matched approved budget and January–June 2025 actuals.
C5: Analysis scope and conventions
C6: Actual period | D6: January–June 2026 recorded actuals
C7: Budget comparison | D7: January–June 2026 approved budget
C8: Prior-year comparison | D8: January–June 2025 recorded actuals
C9: Information cutoff | D9: 46211
C10: Case version | D10: v1.0
C11: Synthetic-data disclosure | D11: Palmetto Stay is fictional. All company-specific actuals, budgets, operating records, staffing information, and case updates are synthetic.
C12: Source references | D12: Data: financial_actuals.csv, operating_actuals.csv, labor_actuals.csv, and case_updates.csv. Budget: approved Budget sheet built from approved_budget_assumptions.csv.
C13: Revenue and contribution | D13: Actual minus Budget. Positive is favorable.
C14: Expense analysis | D14: Actual cost minus Budget cost. Positive is a cost increase and unfavorable.
C15: Contribution bridge expenses | D15: Budget cost minus Actual cost. Positive is favorable to contribution.
C16: Sequential bridges | D16: Revenue uses volume, mix, then rate. Housekeeping uses volume, efficiency, then wage rate. Monthly effects sum to YTD.
C17: Materiality guidance | D17: Review items with absolute YTD variance of at least $10,000, at least 5.0% on a meaningful base, or a known or unresolved qualitative event. A flag is not proof of causation.
C18: Interaction-effect disclosure | D18: Sequential attribution assigns interaction effects according to the stated order. It is a consistent analytical convention, not the only possible causal allocation.
C21: YTD operating scorecard
C22: Revenue and contribution variance: positive is favorable. Expense variance: positive is a cost increase and unfavorable. Occupancy, corporate share, and contribution margin changes are percentage points.
C23: Metric | D23: 2026 Actual | E23: 2026 Budget | F23: Variance / pp | G23: Variance % | H23: 2025 Actual | I23: YoY change / pp | J23: YoY change %
C24: Operating KPIs
C25: Available room nights | D25: =J94 -> 18100 | E25: =J61 -> 18100 | F25: =D25-E25 -> 0 | G25: =IF(E25=0,"n.a.",F25/ABS(E25)) -> 0 | H25: =100*(31+28+31+30+31+30) -> 18100 | I25: =D25-H25 -> 0 | J25: =IF(H25=0,"n.a.",I25/ABS(H25)) -> 0
C26: Occupied room nights | D26: =J95 -> 11538 | E26: =J62 -> 12078 | F26: =D26-E26 -> -540 | G26: =IF(E26=0,"n.a.",F26/ABS(E26)) -> -0.044709389 | H26: =H28+H29 -> 11596 | I26: =D26-H26 -> -58 | J26: =IF(H26=0,"n.a.",I26/ABS(H26)) -> -0.0050017247
C27: Occupancy | D27: =J96 -> 0.63745856 | E27: =J63 -> 0.66729282 | F27: =(D27-E27)*100 -> -2.9834254 | G27: n.a. | H27: =H26/H25 -> 0.64066298 | I27: =(D27-H27)*100 -> -0.32044199 | J27: n.a.
C28: Retail room nights | D28: =J97 -> 7012 | E28: =J64 -> 8058.96 | F28: =D28-E28 -> -1046.96 | G28: =IF(E28=0,"n.a.",F28/ABS(E28)) -> -0.12991254 | H28: =SUM(Data!$F$158,Data!$F$160,Data!$F$162,Data!$F$164,Data!$F$166,Data!$F$168) -> 8040 | I28: =D28-H28 -> -1028 | J28: =IF(H28=0,"n.a.",I28/ABS(H28)) -> -0.1278607
C29: Corporate room nights | D29: =J98 -> 4526 | E29: =J65 -> 4019.04 | F29: =D29-E29 -> 506.96 | G29: =IF(E29=0,"n.a.",F29/ABS(E29)) -> 0.12613958 | H29: =SUM(Data!$F$159,Data!$F$161,Data!$F$163,Data!$F$165,Data!$F$167,Data!$F$169) -> 3556 | I29: =D29-H29 -> 970 | J29: =IF(H29=0,"n.a.",I29/ABS(H29)) -> 0.2727784
C30: Corporate share | D30: =J99 -> 0.39226902 | E30: =J66 -> 0.33275708 | F30: =(D30-E30)*100 -> 5.9511945 | G30: n.a. | H30: =H29/H26 -> 0.30665747 | I30: =(D30-H30)*100 -> 8.5611556 | J30: n.a.
C31: Retail ADR | D31: =J100 -> 163.61737 | E31: =J67 -> 163.69146 | F31: =D31-E31 -> -0.074088725 | G31: =IF(E31=0,"n.a.",F31/ABS(E31)) -> -0.00045261204 | H31: =H36/H28 -> 159.98893 | I31: =D31-H31 -> 3.6284399 | J31: =IF(H31=0,"n.a.",I31/ABS(H31)) -> 0.022679318
C32: Corporate ADR | D32: =J101 -> 140.86942 | E32: =J68 -> 140.29938 | F32: =D32-E32 -> 0.57004117 | G32: =IF(E32=0,"n.a.",F32/ABS(E32)) -> 0.0040630341 | H32: =H37/H29 -> 137.5883 | I32: =D32-H32 -> 3.2811197 | J32: =IF(H32=0,"n.a.",I32/ABS(H32)) -> 0.023847374
C33: Blended ADR | D33: =J102 -> 154.69405 | E33: =J69 -> 155.90758 | F33: =D33-E33 -> -1.2135246 | G33: =IF(E33=0,"n.a.",F33/ABS(E33)) -> -0.0077836154 | H33: =H38/H26 -> 153.11961 | I33: =D33-H33 -> 1.5744442 | J33: =IF(H33=0,"n.a.",I33/ABS(H33)) -> 0.010282447
C34: RevPAR | D34: =J103 -> 98.61105 | E34: =J70 -> 104.03601 | F34: =D34-E34 -> -5.424958 | G34: =IF(E34=0,"n.a.",F34/ABS(E34)) -> -0.052145004 | H34: =H38/H25 -> 98.098066 | I34: =D34-H34 -> 0.51298343 | J34: =IF(H34=0,"n.a.",I34/ABS(H34)) -> 0.0052292919
C35: Financial performance
C36: Retail room revenue | D36: =J104 -> 1147285 | E36: =J71 -> 1319182.9 | F36: =D36-E36 -> -171897.92 | G36: =IF(E36=0,"n.a.",F36/ABS(E36)) -> -0.13030636 | H36: =SUM(Data!$G$158,Data!$G$160,Data!$G$162,Data!$G$164,Data!$G$166,Data!$G$168) -> 1286311 | I36: =D36-H36 -> -139026 | J36: =IF(H36=0,"n.a.",I36/ABS(H36)) -> -0.10808117
C37: Corporate room revenue | D37: =J105 -> 637575 | E37: =J72 -> 563868.82 | F37: =D37-E37 -> 73706.18 | G37: =IF(E37=0,"n.a.",F37/ABS(E37)) -> 0.13071512 | H37: =SUM(Data!$G$159,Data!$G$161,Data!$G$163,Data!$G$165,Data!$G$167,Data!$G$169) -> 489264 | I37: =D37-H37 -> 148311 | J37: =IF(H37=0,"n.a.",I37/ABS(H37)) -> 0.30313083
C38: Total room revenue | D38: =J106 -> 1784860 | E38: =J73 -> 1883051.7 | F38: =D38-E38 -> -98191.74 | G38: =IF(E38=0,"n.a.",F38/ABS(E38)) -> -0.052145004 | H38: =H36+H37 -> 1775575 | I38: =D38-H38 -> 9285 | J38: =IF(H38=0,"n.a.",I38/ABS(H38)) -> 0.0052292919
C39: Housekeeping payroll | D39: =J110 -> 151330.48 | E39: =J77 -> 141578.36 | F39: =D39-E39 -> 9752.12 | G39: =IF(E39=0,"n.a.",F39/ABS(E39)) -> 0.068881431 | H39: =SUM(Data!$F$200,Data!$F$201,Data!$F$202,Data!$F$203,Data!$F$204,Data!$F$205) -> 133869.13 | I39: =D39-H39 -> 17461.35 | J39: =IF(H39=0,"n.a.",I39/ABS(H39)) -> 0.13043597
C40: Guest-service expense | D40: =J112 -> 222931.7 | E40: =J79 -> 231581.3 | F40: =D40-E40 -> -8649.6 | G40: =IF(E40=0,"n.a.",F40/ABS(E40)) -> -0.037350166 | H40: =SUM(Data!$G$10,Data!$G$18,Data!$G$26,Data!$G$34,Data!$G$42,Data!$G$50) -> 215540 | I40: =D40-H40 -> 7391.7 | J40: =IF(H40=0,"n.a.",I40/ABS(H40)) -> 0.034293867
C41: Distribution and payment expense | D41: =J114 -> 71394.4 | E41: =J81 -> 75322.07 | F41: =D41-E41 -> -3927.6696 | G41: =IF(E41=0,"n.a.",F41/ABS(E41)) -> -0.052145004 | H41: =SUM(Data!$G$11,Data!$G$19,Data!$G$27,Data!$G$35,Data!$G$43,Data!$G$51) -> 71023 | I41: =D41-H41 -> 371.4 | J41: =IF(H41=0,"n.a.",I41/ABS(H41)) -> 0.0052292919
C42: Fixed-staff payroll | D42: =J117 -> 180800 | E42: =J84 -> 180000 | F42: =D42-E42 -> 800 | G42: =IF(E42=0,"n.a.",F42/ABS(E42)) -> 0.0044444444 | H42: =SUM(Data!$H$200,Data!$H$201,Data!$H$202,Data!$H$203,Data!$H$204,Data!$H$205) -> 173172 | I42: =D42-H42 -> 7628 | J42: =IF(H42=0,"n.a.",I42/ABS(H42)) -> 0.044048691
C43: Rent | D43: =J118 -> 468000 | E43: =J85 -> 468000 | F43: =D43-E43 -> 0 | G43: =IF(E43=0,"n.a.",F43/ABS(E43)) -> 0 | H43: =SUM(Data!$G$13,Data!$G$21,Data!$G$29,Data!$G$37,Data!$G$45,Data!$G$53) -> 456000 | I43: =D43-H43 -> 12000 | J43: =IF(H43=0,"n.a.",I43/ABS(H43)) -> 0.026315789
C44: Property overhead | D44: =J119 -> 173060 | E44: =J86 -> 171300 | F44: =D44-E44 -> 1760 | G44: =IF(E44=0,"n.a.",F44/ABS(E44)) -> 0.010274372 | H44: =SUM(Data!$G$14,Data!$G$22,Data!$G$30,Data!$G$38,Data!$G$46,Data!$G$54) -> 163600 | I44: =D44-H44 -> 9460 | J44: =IF(H44=0,"n.a.",I44/ABS(H44)) -> 0.057823961
...

Sheet Review
T1: Driver | U1: Contribution impact | W1: Month | X1: Budget | Y1: Actual Jan–Jun / Base RF1 Jul–Dec | AB1: Case | AC1: Property operating contribution
B2: PALMETTO STAY | MANAGEMENT REVIEW | C2: PALMETTO STAY | MANAGEMENT REVIEW | D2: PALMETTO STAY | MANAGEMENT REVIEW | E2: PALMETTO STAY | MANAGEMENT REVIEW | F2: PALMETTO STAY | MANAGEMENT REVIEW | G2: PALMETTO STAY | MANAGEMENT REVIEW | H2: PALMETTO STAY | MANAGEMENT REVIEW | I2: PALMETTO STAY | MANAGEMENT REVIEW | J2: PALMETTO STAY | MANAGEMENT REVIEW | K2: PALMETTO STAY | MANAGEMENT REVIEW | L2: PALMETTO STAY | MANAGEMENT REVIEW | M2: PALMETTO STAY | MANAGEMENT REVIEW | N2: PALMETTO STAY | MANAGEMENT REVIEW | T2: Revenue volume | U2: =Variance!D241 -> -84994.69 | W2: Jan | X2: =Budget!D12*100 -> 55 | Y2: =Variance!D96*100 -> 53.483871 | AB2: Budget | AC2: =Forecast!D16 -> 1279795.4
B3: PALMETTO STAY | MANAGEMENT REVIEW | C3: PALMETTO STAY | MANAGEMENT REVIEW | D3: PALMETTO STAY | MANAGEMENT REVIEW | E3: PALMETTO STAY | MANAGEMENT REVIEW | F3: PALMETTO STAY | MANAGEMENT REVIEW | G3: PALMETTO STAY | MANAGEMENT REVIEW | H3: PALMETTO STAY | MANAGEMENT REVIEW | I3: PALMETTO STAY | MANAGEMENT REVIEW | J3: PALMETTO STAY | MANAGEMENT REVIEW | K3: PALMETTO STAY | MANAGEMENT REVIEW | L3: PALMETTO STAY | MANAGEMENT REVIEW | M3: PALMETTO STAY | MANAGEMENT REVIEW | N3: PALMETTO STAY | MANAGEMENT REVIEW | T3: Customer mix | U3: =Variance!D242 -> -17667.05 | W3: Feb | X3: =Budget!E12*100 -> 58 | Y3: =Variance!E96*100 -> 57.285714 | AB3: Base | AC3: =Forecast!E16 -> 1137547.2
B4: H1 2026 actual performance vs approved budget | Information cutoff: July 8, 2026 | Synthetic case v1.0 | C4: H1 2026 actual performance vs approved budget | Information cutoff: July 8, 2026 | Synthetic case v1.0 | D4: H1 2026 actual performance vs approved budget | Information cutoff: July 8, 2026 | Synthetic case v1.0 | E4: H1 2026 actual performance vs approved budget | Information cutoff: July 8, 2026 | Synthetic case v1.0 | F4: H1 2026 actual performance vs approved budget | Information cutoff: July 8, 2026 | Synthetic case v1.0 | G4: H1 2026 actual performance vs approved budget | Information cutoff: July 8, 2026 | Synthetic case v1.0 | H4: H1 2026 actual performance vs approved budget | Information cutoff: July 8, 2026 | Synthetic case v1.0 | I4: H1 2026 actual performance vs approved budget | Information cutoff: July 8, 2026 | Synthetic case v1.0 | J4: H1 2026 actual performance vs approved budget | Information cutoff: July 8, 2026 | Synthetic case v1.0 | K4: H1 2026 actual performance vs approved budget | Information cutoff: July 8, 2026 | Synthetic case v1.0 | L4: H1 2026 actual performance vs approved budget | Information cutoff: July 8, 2026 | Synthetic case v1.0 | M4: H1 2026 actual performance vs approved budget | Information cutoff: July 8, 2026 | Synthetic case v1.0 | N4: H1 2026 actual performance vs approved budget | Information cutoff: July 8, 2026 | Synthetic case v1.0 | T4: Rate | U4: =Variance!D243 -> 4470 | W4: Mar | X4: =Budget!F12*100 -> 65 | Y4: =Variance!F96*100 -> 62 | AB4: Upside | AC4: =Forecast!G16 -> 1198074
T5: Housekeeping | U5: =SUM(Variance!D244:D246) -> -9752.12 | W5: Apr | X5: =Budget!G12*100 -> 70 | Y5: =Variance!G96*100 -> 65 | AB5: Downside | AC5: =Forecast!I16 -> 1031710.5
B6: H1 PERFORMANCE AT A GLANCE | C6: H1 PERFORMANCE AT A GLANCE | D6: H1 PERFORMANCE AT A GLANCE | E6: H1 PERFORMANCE AT A GLANCE | F6: H1 PERFORMANCE AT A GLANCE | G6: H1 PERFORMANCE AT A GLANCE | H6: H1 PERFORMANCE AT A GLANCE | I6: H1 PERFORMANCE AT A GLANCE | J6: H1 PERFORMANCE AT A GLANCE | K6: H1 PERFORMANCE AT A GLANCE | L6: H1 PERFORMANCE AT A GLANCE | M6: H1 PERFORMANCE AT A GLANCE | N6: H1 PERFORMANCE AT A GLANCE | T6: Guest services | U6: =SUM(Variance!D247:D248) -> 8649.6 | W6: May | X6: =Budget!H12*100 -> 74 | Y6: =Variance!H96*100 -> 69
T7: Distribution | U7: =Variance!D249 -> 3927.6696 | W7: Jun (A) | X7: =Budget!I12*100 -> 78 | Y7: =Variance!I96*100 -> 75.5
B8: Metric | C8: Actual | D8: Budget | E8: Variance | T8: Fixed staff | U8: =SUM(Variance!D250:D251) -> -800 | W8: Jul (F) | X8: =Budget!J12*100 -> 84 | Y8: =Forecast!J33*100 -> 82.322581
B9: Occupancy | C9: =Variance!D27 -> 0.63745856 | D9: =Variance!E27 -> 0.66729282 | E9: =Variance!F27 -> -2.9834254 | T9: Overhead | U9: =Variance!D253 -> -1760 | W9: Aug | X9: =Budget!K12*100 -> 82 | Y9: =Forecast!K33*100 -> 80.354839
B10: Room revenue | C10: =Variance!D38 -> 1784860 | D10: =Variance!E38 -> 1883051.7 | E10: =Variance!F38 -> -98191.74 | T10: Marketing | U10: =Variance!D254 -> 17400 | W10: Sep | X10: =Budget!L12*100 -> 73 | Y10: =Forecast!L33*100 -> 71.533333
B11: Property contribution | C11: =Variance!D47 -> 453743.42 | D11: =Variance!E47 -> 534270.01 | E11: =Variance!F47 -> -80526.59 | W11: Oct | X11: =Budget!M12*100 -> 71 | Y11: =Forecast!M33*100 -> 69.935484
B12: Contribution margin | C12: =Variance!D48 -> 0.25421793 | D12: =Variance!E48 -> 0.28372561 | E12: =Variance!F48 -> -2.9507681 | W12: Nov | X12: =Budget!N12*100 -> 61 | Y12: =Forecast!N33*100 -> 60.4
W13: Dec | X13: =Budget!O12*100 -> 59 | Y13: =Forecast!O33*100 -> 58.419355
B15: MANAGEMENT READOUT | C15: MANAGEMENT READOUT | D15: MANAGEMENT READOUT | E15: MANAGEMENT READOUT | F15: MANAGEMENT READOUT | G15: H1 CONTRIBUTION IMPACT BY DRIVER ($000s) | H15: H1 CONTRIBUTION IMPACT BY DRIVER ($000s) | I15: H1 CONTRIBUTION IMPACT BY DRIVER ($000s) | J15: H1 CONTRIBUTION IMPACT BY DRIVER ($000s) | K15: H1 CONTRIBUTION IMPACT BY DRIVER ($000s) | L15: H1 CONTRIBUTION IMPACT BY DRIVER ($000s) | M15: H1 CONTRIBUTION IMPACT BY DRIVER ($000s) | N15: H1 CONTRIBUTION IMPACT BY DRIVER ($000s)
B16: Demand, not rate, is the primary first-half issue. Lower occupied room nights drove most of the revenue miss, while a richer corporate mix also diluted the benefit of modestly favorable realized rates. | C16: Demand, not rate, is the primary first-half issue. Lower occupied room nights drove most of the revenue miss, while a richer corporate mix also diluted the benefit of modestly favorable realized rates. | D16: Demand, not rate, is the primary first-half issue. Lower occupied room nights drove most of the revenue miss, while a richer corporate mix also diluted the benefit of modestly favorable realized rates. | E16: Demand, not rate, is the primary first-half issue. Lower occupied room nights drove most of the revenue miss, while a richer corporate mix also diluted the benefit of modestly favorable realized rates. | F16: Demand, not rate, is the primary first-half issue. Lower occupied room nights drove most of the revenue miss, while a richer corporate mix also diluted the benefit of modestly favorable realized rates.
B17: Demand, not rate, is the primary first-half issue. Lower occupied room nights drove most of the revenue miss, while a richer corporate mix also diluted the benefit of modestly favorable realized rates. | C17: Demand, not rate, is the primary first-half issue. Lower occupied room nights drove most of the revenue miss, while a richer corporate mix also diluted the benefit of modestly favorable realized rates. | D17: Demand, not rate, is the primary first-half issue. Lower occupied room nights drove most of the revenue miss, while a richer corporate mix also diluted the benefit of modestly favorable realized rates. | E17: Demand, not rate, is the primary first-half issue. Lower occupied room nights drove most of the revenue miss, while a richer corporate mix also diluted the benefit of modestly favorable realized rates. | F17: Demand, not rate, is the primary first-half issue. Lower occupied room nights drove most of the revenue miss, while a richer corporate mix also diluted the benefit of modestly favorable realized rates.
B18: Demand, not rate, is the primary first-half issue. Lower occupied room nights drove most of the revenue miss, while a richer corporate mix also diluted the benefit of modestly favorable realized rates. | C18: Demand, not rate, is the primary first-half issue. Lower occupied room nights drove most of the revenue miss, while a richer corporate mix also diluted the benefit of modestly favorable realized rates. | D18: Demand, not rate, is the primary first-half issue. Lower occupied room nights drove most of the revenue miss, while a richer corporate mix also diluted the benefit of modestly favorable realized rates. | E18: Demand, not rate, is the primary first-half issue. Lower occupied room nights drove most of the revenue miss, while a richer corporate mix also diluted the benefit of modestly favorable realized rates. | F18: Demand, not rate, is the primary first-half issue. Lower occupied room nights drove most of the revenue miss, while a richer corporate mix also diluted the benefit of modestly favorable realized rates.
